<?xml version="1.0" encoding="UTF-8"?>
<!--
Copyright (C) 2020, Raffaello Bonghi <raffaello@rnext.it>
All rights reserved

Redistribution and use in source and binary forms, with or without
modification, are permitted provided that the following conditions are met:

1. Redistributions of source code must retain the above copyright 
   notice, this list of conditions and the following disclaimer.
2. Redistributions in binary form must reproduce the above copyright
   notice, this list of conditions and the following disclaimer in the
   documentation and/or other materials provided with the distribution.
3. Neither the name of the copyright holder nor the names of its 
   contributors may be used to endorse or promote products derived 
   from this software without specific prior written permission.
 
THIS SOFTWARE IS PROVIDED BY THE COPYRIGHT HOLDERS AND 
CONTRIBUTORS "AS IS" AND ANY EXPRESS OR IMPLIED WARRANTIES, INCLUDING, 
BUT NOT LIMITED TO, THE IMPLIED WARRANTIES OF MERCHANTABILITY AND FITNESS 
FOR A PARTICULAR PURPOSE ARE DISCLAIMED. IN NO EVENT SHALL THE COPYRIGHT
HOLDER OR CONTRIBUTORS BE LIABLE FOR ANY DIRECT, INDIRECT, INCIDENTAL, 
SPECIAL, EXEMPLARY, OR CONSEQUENTIAL DAMAGES (INCLUDING, BUT NOT LIMITED TO,
PROCUREMENT OF SUBSTITUTE GOODS OR SERVICES; LOSS OF USE, DATA, OR PROFITS; 
OR BUSINESS INTERRUPTION) HOWEVER CAUSED AND ON ANY THEORY OF LIABILITY, 
WHETHER IN CONTRACT, STRICT LIABILITY, OR TORT (INCLUDING NEGLIGENCE 
OR OTHERWISE) ARISING IN ANY WAY OUT OF THE USE OF THIS SOFTWARE, 
EVEN IF ADVISED OF THE POSSIBILITY OF SUCH DAMAGE.
-->
<sdf version="1.5">
   <world name="default">
      <light name="sun" type="directional">
         <cast_shadows>1</cast_shadows>
         <pose>0 0 10 0 -0 0</pose>
         <diffuse>0.8 0.8 0.8 1</diffuse>
         <specular>0.2 0.2 0.2 1</specular>
         <attenuation>
            <range>1000</range>
            <constant>0.9</constant>
            <linear>0.01</linear>
            <quadratic>0.001</quadratic>
         </attenuation>
         <direction>-0.5 0.1 -0.9</direction>
      </light>
      <model name="ground_plane">
         <static>1</static>
         <link name="link">
            <collision name="collision">
               <geometry>
                  <plane>
                     <normal>0 0 1</normal>
                     <size>100 100</size>
                  </plane>
               </geometry>
               <surface>
                  <friction>
                     <ode>
                        <mu>100</mu>
                        <mu2>50</mu2>
                     </ode>
                  </friction>
                  <contact>
                     <ode />
                  </contact>
                  <bounce />
               </surface>
               <max_contacts>10</max_contacts>
            </collision>
            <visual name="visual">
               <cast_shadows>0</cast_shadows>
               <geometry>
                  <plane>
                     <normal>0 0 1</normal>
                     <size>100 100</size>
                  </plane>
               </geometry>
               <material>
                  <script>
                     <uri>file://media/materials/scripts/gazebo.material</uri>
                     <name>Gazebo/Grey</name>
                  </script>
               </material>
            </visual>
            <self_collide>0</self_collide>
            <kinematic>0</kinematic>
            <gravity>1</gravity>
         </link>
      </model>
      <physics name="default_physics" default="0" type="ode">
         <max_step_size>0.001</max_step_size>
         <real_time_factor>1</real_time_factor>
         <real_time_update_rate>1000</real_time_update_rate>
         <gravity>0 0 -9.8</gravity>
         <magnetic_field>5.5645e-06 2.28758e-05 -4.23884e-05</magnetic_field>
      </physics>
      <scene>
         <ambient>0.4 0.4 0.4 1</ambient>
         <background>0.7 0.7 0.7 1</background>
         <shadows>1</shadows>
      </scene>
      <spherical_coordinates>
         <surface_model>EARTH_WGS84</surface_model>
         <latitude_deg>0</latitude_deg>
         <longitude_deg>0</longitude_deg>
         <elevation>0</elevation>
         <heading_deg>0</heading_deg>
      </spherical_coordinates>
      <model name="cafe">
         <static>1</static>
         <link name="link">
            <collision name="main_floor">
               <pose>-0.4 -0.75 0.0948 0 -0 0</pose>
               <geometry>
                  <box>
                     <size>9.38 22.63 0.19</size>
                  </box>
               </geometry>
               <max_contacts>10</max_contacts>
               <surface>
                  <contact>
                     <ode />
                  </contact>
                  <bounce />
                  <friction>
                     <ode />
                  </friction>
               </surface>
            </collision>
            <collision name="wall_1">
               <pose>-5.03 0.53 1.415 0 -0 0</pose>
               <geometry>
                  <box>
                     <size>0.12 23.16 2.83</size>
                  </box>
               </geometry>
               <max_contacts>10</max_contacts>
               <surface>
                  <contact>
                     <ode />
                  </contact>
                  <bounce />
                  <friction>
                     <ode />
                  </friction>
               </surface>
            </collision>
            <collision name="wall_2">
               <pose>4.24 -0.31 1.415 0 -0 0</pose>
               <geometry>
                  <box>
                     <size>0.12 21.48 2.83</size>
                  </box>
               </geometry>
               <max_contacts>10</max_contacts>
               <surface>
                  <contact>
                     <ode />
                  </contact>
                  <bounce />
                  <friction>
                     <ode />
                  </friction>
               </surface>
            </collision>
            <collision name="wall_3">
               <pose>-1.48 7.43 1.415 0 -0 0</pose>
               <geometry>
                  <box>
                     <size>7.2 0.12 2.83</size>
                  </box>
               </geometry>
               <max_contacts>10</max_contacts>
               <surface>
                  <contact>
                     <ode />
                  </contact>
                  <bounce />
                  <friction>
                     <ode />
                  </friction>
               </surface>
            </collision>
            <collision name="wall_4">
               <pose>2.09 8.9 1.435 0 -0 0</pose>
               <geometry>
                  <box>
                     <size>0.12 3.05 2.87</size>
                  </box>
               </geometry>
               <max_contacts>10</max_contacts>
               <surface>
                  <contact>
                     <ode />
                  </contact>
                  <bounce />
                  <friction>
                     <ode />
                  </friction>
               </surface>
            </collision>
            <collision name="wall_5">
               <pose>3.155 10.4 1.435 0 -0 0</pose>
               <geometry>
                  <box>
                     <size>2.13 0.12 2.87</size>
                  </box>
               </geometry>
               <max_contacts>10</max_contacts>
               <surface>
                  <contact>
                     <ode />
                  </contact>
                  <bounce />
                  <friction>
                     <ode />
                  </friction>
               </surface>
            </collision>
            <collision name="wall_6">
               <pose>0.615 -10.98 1.415 0 -0 0</pose>
               <geometry>
                  <box>
                     <size>7.36 0.15 2.83</size>
                  </box>
               </geometry>
               <max_contacts>10</max_contacts>
               <surface>
                  <contact>
                     <ode />
                  </contact>
                  <bounce />
                  <friction>
                     <ode />
                  </friction>
               </surface>
            </collision>
            <collision name="wall_7">
               <pose>-4.62 -10.98 1.415 0 -0 0</pose>
               <geometry>
                  <box>
                     <size>0.93 0.15 2.83</size>
                  </box>
               </geometry>
               <max_contacts>10</max_contacts>
               <surface>
                  <contact>
                     <ode />
                  </contact>
                  <bounce />
                  <friction>
                     <ode />
                  </friction>
               </surface>
            </collision>
            <collision name="wall_8">
               <pose>-3.61 -10.98 2.69 0 -0 0</pose>
               <geometry>
                  <box>
                     <size>1.09 0.15 0.28</size>
                  </box>
               </geometry>
               <max_contacts>10</max_contacts>
               <surface>
                  <contact>
                     <ode />
                  </contact>
                  <bounce />
                  <friction>
                     <ode />
                  </friction>
               </surface>
            </collision>
            <collision name="coke">
               <pose>-4.385 0.26 0.95 0 -0 0</pose>
               <geometry>
                  <box>
                     <size>1.03 1.03 1.52</size>
                  </box>
               </geometry>
               <max_contacts>10</max_contacts>
               <surface>
                  <contact>
                     <ode />
                  </contact>
                  <bounce />
                  <friction>
                     <ode />
                  </friction>
               </surface>
            </collision>
            <visual name="visual">
               <geometry>
                  <mesh>
                     <uri>model://cafe/meshes/cafe.dae</uri>
                  </mesh>
               </geometry>
            </visual>
            <self_collide>0</self_collide>
            <kinematic>0</kinematic>
            <gravity>1</gravity>
         </link>
         <pose>0.547429 -1.42394 0 0 -0 0</pose>
      </model>
      <model name="cafe_table_0">
         <static>1</static>
         <link name="link">
            <collision name="surface">
               <pose>0 0 0.755 0 -0 0</pose>
               <geometry>
                  <box>
                     <size>0.913 0.913 0.04</size>
                  </box>
               </geometry>
               <max_contacts>10</max_contacts>
               <surface>
                  <contact>
                     <ode />
                  </contact>
                  <bounce />
                  <friction>
                     <ode />
                  </friction>
               </surface>
            </collision>
            <collision name="column">
               <pose>0 0 0.37 0 -0 0</pose>
               <geometry>
                  <box>
                     <size>0.042 0.042 0.74</size>
                  </box>
               </geometry>
               <max_contacts>10</max_contacts>
               <surface>
                  <contact>
                     <ode />
                  </contact>
                  <bounce />
                  <friction>
                     <ode />
                  </friction>
               </surface>
            </collision>
            <collision name="base">
               <pose>0 0 0.02 0 -0 0</pose>
               <geometry>
                  <box>
                     <size>0.56 0.56 0.04</size>
                  </box>
               </geometry>
               <max_contacts>10</max_contacts>
               <surface>
                  <contact>
                     <ode />
                  </contact>
                  <bounce />
                  <friction>
                     <ode />
                  </friction>
               </surface>
            </collision>
            <visual name="visual">
               <geometry>
                  <mesh>
                     <uri>model://cafe_table/meshes/cafe_table.dae</uri>
                  </mesh>
               </geometry>
            </visual>
            <self_collide>0</self_collide>
            <kinematic>0</kinematic>
            <gravity>1</gravity>
         </link>
         <pose>-2 -5 0 0 -0 0</pose>
      </model>
      <model name="cafe_table_1">
         <static>1</static>
         <link name="link">
            <collision name="surface">
               <pose>0 0 0.755 0 -0 0</pose>
               <geometry>
                  <box>
                     <size>0.913 0.913 0.04</size>
                  </box>
               </geometry>
               <max_contacts>10</max_contacts>
               <surface>
                  <contact>
                     <ode />
                  </contact>
                  <bounce />
                  <friction>
                     <ode />
                  </friction>
               </surface>
            </collision>
            <collision name="column">
               <pose>0 0 0.37 0 -0 0</pose>
               <geometry>
                  <box>
                     <size>0.042 0.042 0.74</size>
                  </box>
               </geometry>
               <max_contacts>10</max_contacts>
               <surface>
                  <contact>
                     <ode />
                  </contact>
                  <bounce />
                  <friction>
                     <ode />
                  </friction>
               </surface>
            </collision>
            <collision name="base">
               <pose>0 0 0.02 0 -0 0</pose>
               <geometry>
                  <box>
                     <size>0.56 0.56 0.04</size>
                  </box>
               </geometry>
               <max_contacts>10</max_contacts>
               <surface>
                  <contact>
                     <ode />
                  </contact>
                  <bounce />
                  <friction>
                     <ode />
                  </friction>
               </surface>
            </collision>
            <visual name="visual">
               <geometry>
                  <mesh>
                     <uri>model://cafe_table/meshes/cafe_table.dae</uri>
                  </mesh>
               </geometry>
            </visual>
            <self_collide>0</self_collide>
            <kinematic>0</kinematic>
            <gravity>1</gravity>
         </link>
         <pose>0 -7 0 0 -0 0</pose>
      </model>
      <model name="cafe_table_2">
         <static>1</static>
         <link name="link">
            <collision name="surface">
               <pose>0 0 0.755 0 -0 0</pose>
               <geometry>
                  <box>
                     <size>0.913 0.913 0.04</size>
                  </box>
               </geometry>
               <max_contacts>10</max_contacts>
               <surface>
                  <contact>
                     <ode />
                  </contact>
                  <bounce />
                  <friction>
                     <ode />
                  </friction>
               </surface>
            </collision>
            <collision name="column">
               <pose>0 0 0.37 0 -0 0</pose>
               <geometry>
                  <box>
                     <size>0.042 0.042 0.74</size>
                  </box>
               </geometry>
               <max_contacts>10</max_contacts>
               <surface>
                  <contact>
                     <ode />
                  </contact>
                  <bounce />
                  <friction>
                     <ode />
                  </friction>
               </surface>
            </collision>
            <collision name="base">
               <pose>0 0 0.02 0 -0 0</pose>
               <geometry>
                  <box>
                     <size>0.56 0.56 0.04</size>
                  </box>
               </geometry>
               <max_contacts>10</max_contacts>
               <surface>
                  <contact>
                     <ode />
                  </contact>
                  <bounce />
                  <friction>
                     <ode />
                  </friction>
               </surface>
            </collision>
            <visual name="visual">
               <geometry>
                  <mesh>
                     <uri>model://cafe_table/meshes/cafe_table.dae</uri>
                  </mesh>
               </geometry>
            </visual>
            <self_collide>0</self_collide>
            <kinematic>0</kinematic>
            <gravity>1</gravity>
         </link>
         <pose>-2 -8 0 0 -0 0</pose>
      </model>
      <model name="husky">
         <pose>-3 -10 0.5 0 -0 0</pose>
         <link name="base_link">
            <collision name="collision">
               <pose>0 0 0.1 0 -0 0</pose>
               <geometry>
                  <box>
                     <size>1.0074 0.5709 0.2675</size>
                  </box>
               </geometry>
               <max_contacts>10</max_contacts>
               <surface>
                  <contact>
                     <ode />
                  </contact>
                  <bounce />
                  <friction>
                     <ode />
                  </friction>
               </surface>
            </collision>
            <inertial>
               <mass>33.855</mass>
               <pose>-0.0856132 -0.000839955 0.238145 0 -0 0</pose>
               <inertia>
                  <ixx>2.2343</ixx>
                  <ixy>-0.023642</ixy>
                  <ixz>0.275174</ixz>
                  <iyy>3.42518</iyy>
                  <iyz>0.00239624</iyz>
                  <izz>2.1241</izz>
               </inertia>
            </inertial>
            <visual name="base">
               <pose>0 0 0 0 -0 0</pose>
               <geometry>
                  <mesh>
                     <uri>model://husky/meshes/base_link.stl</uri>
                  </mesh>
               </geometry>
               <material>
                  <script>
                     <name>Gazebo/FlatBlack</name>
                     <uri>__default__</uri>
                  </script>
               </material>
            </visual>
            <visual name="top_plate">
               <pose>0 0 0 0 -0 0</pose>
               <geometry>
                  <mesh>
                     <uri>model://husky/meshes/top_plate.stl</uri>
                  </mesh>
               </geometry>
               <material>
                  <script>
                     <name>Gazebo/Yellow</name>
                     <uri>__default__</uri>
                  </script>
               </material>
            </visual>
            <visual name="front_bumper">
               <pose>0.47 0 0.091 0 -0 0</pose>
               <geometry>
                  <mesh>
                     <uri>model://husky/meshes/bumper.stl</uri>
                  </mesh>
               </geometry>
               <material>
                  <script>
                     <name>Gazebo/FlatBlack</name>
                     <uri>__default__</uri>
                  </script>
               </material>
            </visual>
            <visual name="rear_bumper">
               <pose>-0.47 0 0.091 0 -0 3.141</pose>
               <geometry>
                  <mesh>
                     <uri>model://husky/meshes/bumper.stl</uri>
                  </mesh>
               </geometry>
               <material>
                  <script>
                     <name>Gazebo/FlatBlack</name>
                     <uri>__default__</uri>
                  </script>
               </material>
            </visual>
            <visual name="user_rail">
               <pose>0.272 0 0.245 0 -0 0</pose>
               <geometry>
                  <mesh>
                     <uri>model://husky/meshes/user_rail.stl</uri>
                  </mesh>
               </geometry>
               <material>
                  <script>
                     <name>Gazebo/Grey</name>
                     <uri>__default__</uri>
                  </script>
               </material>
            </visual>
            <self_collide>0</self_collide>
            <kinematic>0</kinematic>
            <gravity>1</gravity>
         </link>
         <link name="back_left_wheel">
            <pose>-0.256 0.285475 0.035 0 -0 0</pose>
            <inertial>
               <mass>2.6357</mass>
               <pose>0 0 0 0 -0 0</pose>
               <inertia>
                  <ixx>0.0246688</ixx>
                  <ixy>0</ixy>
                  <ixz>0</ixz>
                  <iyy>0.0246688</iyy>
                  <iyz>0</iyz>
                  <izz>0.0441058</izz>
               </inertia>
            </inertial>
            <collision name="back_left_wheel_collision">
               <pose>0 0 0 -1.5707 0 0</pose>
               <geometry>
                  <cylinder>
                     <radius>0.17775</radius>
                     <length>0.1143</length>
                  </cylinder>
               </geometry>
               <surface>
                  <friction>
                     <ode>
                        <mu>100000</mu>
                        <mu2>100000</mu2>
                        <slip1>0</slip1>
                        <slip2>0</slip2>
                     </ode>
                  </friction>
                  <contact>
                     <ode />
                  </contact>
                  <bounce />
               </surface>
               <max_contacts>10</max_contacts>
            </collision>
            <visual name="back_left_wheel">
               <pose>0 0 0 -3.14159 0 0</pose>
               <geometry>
                  <mesh>
                     <uri>model://husky/meshes/wheel.stl</uri>
                  </mesh>
               </geometry>
               <material>
                  <script>
                     <name>Gazebo/Grey</name>
                     <uri>__default__</uri>
                  </script>
               </material>
            </visual>
            <self_collide>0</self_collide>
            <kinematic>0</kinematic>
            <gravity>1</gravity>
         </link>
         <joint name="back_left_joint" type="revolute">
            <parent>base_link</parent>
            <child>back_left_wheel</child>
            <axis>
               <xyz>0 1 0</xyz>
               <use_parent_model_frame>1</use_parent_model_frame>
               <limit>
                  <lower>-1e+16</lower>
                  <upper>1e+16</upper>
               </limit>
               <dynamics>
                  <spring_reference>0</spring_reference>
                  <spring_stiffness>0</spring_stiffness>
               </dynamics>
            </axis>
            <physics>
               <ode>
                  <limit>
                     <cfm>0</cfm>
                     <erp>0.9</erp>
                  </limit>
               </ode>
            </physics>
         </joint>
         <link name="back_right_wheel">
            <pose>-0.256 -0.285475 0.035 0 -0 0</pose>
            <inertial>
               <mass>2.6357</mass>
               <pose>0 0 0 0 -0 0</pose>
               <inertia>
                  <ixx>0.0246688</ixx>
                  <ixy>0</ixy>
                  <ixz>0</ixz>
                  <iyy>0.0246688</iyy>
                  <iyz>0</iyz>
                  <izz>0.0441058</izz>
               </inertia>
            </inertial>
            <collision name="back_right_wheel_collision">
               <pose>0 0 0 -1.5707 0 0</pose>
               <geometry>
                  <cylinder>
                     <radius>0.17775</radius>
                     <length>0.1143</length>
                  </cylinder>
               </geometry>
               <surface>
                  <friction>
                     <ode>
                        <mu>100000</mu>
                        <mu2>100000</mu2>
                        <slip1>0</slip1>
                        <slip2>0</slip2>
                     </ode>
                  </friction>
                  <contact>
                     <ode />
                  </contact>
                  <bounce />
               </surface>
               <max_contacts>10</max_contacts>
            </collision>
            <visual name="back_right_wheel">
               <pose>0 0 0 -3.14159 0 0</pose>
               <geometry>
                  <mesh>
                     <uri>model://husky/meshes/wheel.stl</uri>
                  </mesh>
               </geometry>
               <material>
                  <script>
                     <name>Gazebo/Grey</name>
                     <uri>__default__</uri>
                  </script>
               </material>
            </visual>
            <self_collide>0</self_collide>
            <kinematic>0</kinematic>
            <gravity>1</gravity>
         </link>
         <joint name="back_right_joint" type="revolute">
            <parent>base_link</parent>
            <child>back_right_wheel</child>
            <axis>
               <xyz>0 1 0</xyz>
               <use_parent_model_frame>1</use_parent_model_frame>
               <limit>
                  <lower>-1e+16</lower>
                  <upper>1e+16</upper>
               </limit>
               <dynamics>
                  <spring_reference>0</spring_reference>
                  <spring_stiffness>0</spring_stiffness>
               </dynamics>
            </axis>
            <physics>
               <ode>
                  <limit>
                     <cfm>0</cfm>
                     <erp>0.9</erp>
                  </limit>
               </ode>
            </physics>
         </joint>
         <link name="front_left_wheel">
            <pose>0.256 0.285475 0.035 0 -0 0</pose>
            <inertial>
               <mass>2.6357</mass>
               <pose>0 0 0 0 -0 0</pose>
               <inertia>
                  <ixx>0.0246688</ixx>
                  <ixy>0</ixy>
                  <ixz>0</ixz>
                  <iyy>0.0246688</iyy>
                  <iyz>0</iyz>
                  <izz>0.0441058</izz>
               </inertia>
            </inertial>
            <collision name="front_left_wheel_collision">
               <pose>0 0 0 -1.5707 0 0</pose>
               <geometry>
                  <cylinder>
                     <radius>0.17775</radius>
                     <length>0.1143</length>
                  </cylinder>
               </geometry>
               <surface>
                  <friction>
                     <ode>
                        <mu>100000</mu>
                        <mu2>100000</mu2>
                        <slip1>0</slip1>
                        <slip2>0</slip2>
                     </ode>
                  </friction>
                  <contact>
                     <ode />
                  </contact>
                  <bounce />
               </surface>
               <max_contacts>10</max_contacts>
            </collision>
            <visual name="front_left_wheel">
               <pose>0 0 0 -3.14159 0 0</pose>
               <geometry>
                  <mesh>
                     <uri>model://husky/meshes/wheel.stl</uri>
                  </mesh>
               </geometry>
               <material>
                  <script>
                     <name>Gazebo/Grey</name>
                     <uri>__default__</uri>
                  </script>
               </material>
            </visual>
            <self_collide>0</self_collide>
            <kinematic>0</kinematic>
            <gravity>1</gravity>
         </link>
         <joint name="front_left_joint" type="revolute">
            <parent>base_link</parent>
            <child>front_left_wheel</child>
            <axis>
               <xyz>0 1 0</xyz>
               <use_parent_model_frame>1</use_parent_model_frame>
               <limit>
                  <lower>-1e+16</lower>
                  <upper>1e+16</upper>
               </limit>
               <dynamics>
                  <spring_reference>0</spring_reference>
                  <spring_stiffness>0</spring_stiffness>
               </dynamics>
            </axis>
            <physics>
               <ode>
                  <limit>
                     <cfm>0</cfm>
                     <erp>0.9</erp>
                  </limit>
               </ode>
            </physics>
         </joint>
         <link name="front_right_wheel">
            <pose>0.256 -0.285475 0.035 0 -0 0</pose>
            <inertial>
               <mass>2.6357</mass>
               <pose>0 0 0 0 -0 0</pose>
               <inertia>
                  <ixx>0.0246688</ixx>
                  <ixy>0</ixy>
                  <ixz>0</ixz>
                  <iyy>0.0246688</iyy>
                  <iyz>0</iyz>
                  <izz>0.0441058</izz>
               </inertia>
            </inertial>
            <collision name="front_right_wheel_collision">
               <pose>0 0 0 -1.5707 0 0</pose>
               <geometry>
                  <cylinder>
                     <radius>0.17775</radius>
                     <length>0.1143</length>
                  </cylinder>
               </geometry>
               <surface>
                  <friction>
                     <ode>
                        <mu>100000</mu>
                        <mu2>100000</mu2>
                        <slip1>0</slip1>
                        <slip2>0</slip2>
                     </ode>
                  </friction>
                  <contact>
                     <ode />
                  </contact>
                  <bounce />
               </surface>
               <max_contacts>10</max_contacts>
            </collision>
            <visual name="front_right_wheel">
               <pose>0 0 0 -3.14159 0 0</pose>
               <geometry>
                  <mesh>
                     <uri>model://husky/meshes/wheel.stl</uri>
                  </mesh>
               </geometry>
               <material>
                  <script>
                     <name>Gazebo/Grey</name>
                     <uri>__default__</uri>
                  </script>
               </material>
            </visual>
            <self_collide>0</self_collide>
            <kinematic>0</kinematic>
            <gravity>1</gravity>
         </link>
         <joint name="front_right_joint" type="revolute">
            <parent>base_link</parent>
            <child>front_right_wheel</child>
            <axis>
               <xyz>0 1 0</xyz>
               <use_parent_model_frame>1</use_parent_model_frame>
               <limit>
                  <lower>-1e+16</lower>
                  <upper>1e+16</upper>
               </limit>
               <dynamics>
                  <spring_reference>0</spring_reference>
                  <spring_stiffness>0</spring_stiffness>
               </dynamics>
            </axis>
            <physics>
               <ode>
                  <limit>
                     <cfm>0</cfm>
                     <erp>0.9</erp>
                  </limit>
               </ode>
            </physics>
         </joint>
         <plugin name="husky_diff_controller" filename="libhusky_gazebo_plugins.so">
            <alwaysOn>true</alwaysOn>
            <updateRate>100.0</updateRate>
            <backLeftJoint>back_left_joint</backLeftJoint>
            <backRightJoint>back_right_joint</backRightJoint>
            <frontLeftJoint>front_left_joint</frontLeftJoint>
            <frontRightJoint>front_right_joint</frontRightJoint>
            <wheelSeparation>0.5709</wheelSeparation>
            <wheelDiameter>0.3555</wheelDiameter>
            <torque>35</torque>
         </plugin>
      </model>
      <model name="youbot">
         <pose>2 0 0.09 0 -0 0</pose>
         <link name="base_footprint">
            <pose>0 0 0 0 -0 0</pose>
            <inertial>
               <pose>0 0 -0.05 0 -0 0</pose>
               <inertia>
                  <ixx>1</ixx>
                  <ixy>0</ixy>
                  <ixz>0</ixz>
                  <iyy>1</iyy>
                  <iyz>0</iyz>
                  <izz>1</izz>
               </inertia>
               <mass>0.1</mass>
            </inertial>
            <collision name="base_footprint_geom">
               <pose>0 0 -0.05 0 -0 0</pose>
               <geometry>
                  <box>
                     <size>0.001 0.001 0.001</size>
                  </box>
               </geometry>
               <surface>
                  <friction>
                     <ode>
                        <mu>0</mu>
                        <mu2>0</mu2>
                        <fdir1>0 0 0</fdir1>
                        <slip1>0</slip1>
                        <slip2>0</slip2>
                     </ode>
                  </friction>
                  <bounce>
                     <restitution_coefficient>0</restitution_coefficient>
                     <threshold>0</threshold>
                  </bounce>
                  <contact>
                     <ode>
                        <soft_cfm>0</soft_cfm>
                        <soft_erp>0.2</soft_erp>
                        <kp>1e+13</kp>
                        <kd>1e+11</kd>
                        <max_vel>-1</max_vel>
                        <min_depth>0</min_depth>
                     </ode>
                  </contact>
               </surface>
               <laser_retro>0</laser_retro>
               <max_contacts>10</max_contacts>
            </collision>
            <visual name="base_footprint_geom_visual">
               <pose>0 0 0 0 -0 0</pose>
               <geometry>
                  <box>
                     <size>0.001 0.001 0.001</size>
                  </box>
               </geometry>
            </visual>
            <gravity>1</gravity>
            <self_collide>0</self_collide>
            <kinematic>0</kinematic>
         </link>
         <link name="base_link">
            <pose>0 0 0 0 -0 0</pose>
            <inertial>
               <pose>0 0 0 0 -0 0</pose>
               <inertia>
                  <ixx>5.65223</ixx>
                  <ixy>-0.00972</ixy>
                  <ixz>1.29399</ixz>
                  <iyy>5.66947</iyy>
                  <iyz>-0.00738</iyz>
                  <izz>3.6832</izz>
               </inertia>
               <mass>22</mass>
            </inertial>
            <collision name="base_link_geom">
               <pose>0 0 0 0 -0 0</pose>
               <geometry>
                  <mesh>
                     <uri>model://youbot/meshes/base/base_convex.stl</uri>
                  </mesh>
               </geometry>
               <surface>
                  <friction>
                     <ode>
                        <mu>0</mu>
                        <mu2>0</mu2>
                        <fdir1>0 0 0</fdir1>
                        <slip1>0</slip1>
                        <slip2>0</slip2>
                     </ode>
                  </friction>
                  <bounce>
                     <restitution_coefficient>0</restitution_coefficient>
                     <threshold>0</threshold>
                  </bounce>
                  <contact>
                     <ode>
                        <soft_cfm>0</soft_cfm>
                        <soft_erp>0.2</soft_erp>
                        <kp>1e+13</kp>
                        <kd>1e+11</kd>
                        <max_vel>-1</max_vel>
                        <min_depth>0</min_depth>
                     </ode>
                  </contact>
               </surface>
               <laser_retro>0</laser_retro>
               <max_contacts>10</max_contacts>
            </collision>
            <visual name="base_link_geom_visual">
               <pose>0 0 0 0 -0 0</pose>
               <geometry>
                  <mesh>
                     <uri>model://youbot/meshes/base/base.dae</uri>
                  </mesh>
               </geometry>
            </visual>
            <gravity>1</gravity>
            <self_collide>0</self_collide>
            <kinematic>0</kinematic>
         </link>
         <link name="arm_link_0">
            <pose>0.143 0 0.046 0 -0 0</pose>
            <inertial>
               <pose>0 0 0 0 -0 0</pose>
               <inertia>
                  <ixx>0.01</ixx>
                  <ixy>0</ixy>
                  <ixz>0</ixz>
                  <iyy>0.01</iyy>
                  <iyz>0</iyz>
                  <izz>0.01</izz>
               </inertia>
               <mass>0.845</mass>
            </inertial>
            <collision name="arm_link_0_geom">
               <pose>0 0 0 0 -0 0</pose>
               <geometry>
                  <mesh>
                     <uri>model://youbot/meshes/arm/arm0_convex.stl</uri>
                  </mesh>
               </geometry>
               <surface>
                  <friction>
                     <ode>
                        <mu>0</mu>
                        <mu2>0</mu2>
                        <fdir1>0 0 0</fdir1>
                        <slip1>0</slip1>
                        <slip2>0</slip2>
                     </ode>
                  </friction>
                  <bounce>
                     <restitution_coefficient>0</restitution_coefficient>
                     <threshold>0</threshold>
                  </bounce>
                  <contact>
                     <ode>
                        <soft_cfm>0</soft_cfm>
                        <soft_erp>0.2</soft_erp>
                        <kp>1e+13</kp>
                        <kd>1e+11</kd>
                        <max_vel>-1</max_vel>
                        <min_depth>0</min_depth>
                     </ode>
                  </contact>
               </surface>
               <laser_retro>0</laser_retro>
               <max_contacts>10</max_contacts>
            </collision>
            <visual name="arm_link_0_geom_visual">
               <pose>0 0 0 0 -0 0</pose>
               <geometry>
                  <mesh>
                     <uri>model://youbot/meshes/arm/arm0.dae</uri>
                  </mesh>
               </geometry>
               <material>
                  <script>
                     <uri>model://youbot/materials/scripts/youbot.material</uri>
                     <name>youbot/DarkGrey</name>
                  </script>
               </material>
            </visual>
            <gravity>1</gravity>
            <self_collide>0</self_collide>
            <kinematic>0</kinematic>
         </link>
         <link name="arm_link_1">
            <pose>0.167 0 0.142 0 -0 2.96706</pose>
            <inertial>
               <pose>0.01489 0.00213 0.00213 0 -0 0</pose>
               <inertia>
                  <ixx>0.003863</ixx>
                  <ixy>-0.000979</ixy>
                  <ixz>0</ixz>
                  <iyy>0.006196</iyy>
                  <iyz>0</iyz>
                  <izz>0.006369</izz>
               </inertia>
               <mass>2.412</mass>
            </inertial>
            <collision name="arm_link_1_geom">
               <pose>0 0 0 0 -0 0</pose>
               <geometry>
                  <mesh>
                     <uri>model://youbot/meshes/arm/arm1_convex.stl</uri>
                  </mesh>
               </geometry>
               <surface>
                  <friction>
                     <ode>
                        <mu>0</mu>
                        <mu2>0</mu2>
                        <fdir1>0 0 0</fdir1>
                        <slip1>0</slip1>
                        <slip2>0</slip2>
                     </ode>
                  </friction>
                  <bounce>
                     <restitution_coefficient>0</restitution_coefficient>
                     <threshold>0</threshold>
                  </bounce>
                  <contact>
                     <ode>
                        <soft_cfm>0</soft_cfm>
                        <soft_erp>0.2</soft_erp>
                        <kp>1e+13</kp>
                        <kd>1e+11</kd>
                        <max_vel>-1</max_vel>
                        <min_depth>0</min_depth>
                     </ode>
                  </contact>
               </surface>
               <laser_retro>0</laser_retro>
               <max_contacts>10</max_contacts>
            </collision>
            <visual name="arm_link_1_geom_visual">
               <pose>0 0 0 0 -0 0</pose>
               <geometry>
                  <mesh>
                     <uri>model://youbot/meshes/arm/arm1.dae</uri>
                  </mesh>
               </geometry>
            </visual>
            <gravity>1</gravity>
            <self_collide>0</self_collide>
            <kinematic>0</kinematic>
         </link>
         <link name="arm_link_2">
            <pose>0.134501 0.00573 0.161 1.31349e-16 -1.13446 2.96706</pose>
            <inertial>
               <pose>0.10453 0.0017 -0.00297 0 -0 0</pose>
               <inertia>
                  <ixx>0.000823</ixx>
                  <ixy>0</ixy>
                  <ixz>-0</ixz>
                  <iyy>0.004447</iyy>
                  <iyz>0</iyz>
                  <izz>0.004439</izz>
               </inertia>
               <mass>1.155</mass>
            </inertial>
            <collision name="arm_link_2_geom">
               <pose>0 -0.032 0.078 0 -0 0</pose>
               <geometry>
                  <mesh>
                     <uri>model://youbot/meshes/arm/arm2_convex.stl</uri>
                  </mesh>
               </geometry>
               <surface>
                  <friction>
                     <ode>
                        <mu>0</mu>
                        <mu2>0</mu2>
                        <fdir1>0 0 0</fdir1>
                        <slip1>0</slip1>
                        <slip2>0</slip2>
                     </ode>
                  </friction>
                  <bounce>
                     <restitution_coefficient>0</restitution_coefficient>
                     <threshold>0</threshold>
                  </bounce>
                  <contact>
                     <ode>
                        <soft_cfm>0</soft_cfm>
                        <soft_erp>0.2</soft_erp>
                        <kp>1e+13</kp>
                        <kd>1e+11</kd>
                        <max_vel>-1</max_vel>
                        <min_depth>0</min_depth>
                     </ode>
                  </contact>
               </surface>
               <laser_retro>0</laser_retro>
               <max_contacts>10</max_contacts>
            </collision>
            <visual name="arm_link_2_geom_visual">
               <pose>0 -0.032 0.078 0 -0 0</pose>
               <geometry>
                  <mesh>
                     <uri>model://youbot/meshes/arm/arm2.dae</uri>
                  </mesh>
               </geometry>
            </visual>
            <gravity>1</gravity>
            <self_collide>0</self_collide>
            <kinematic>0</kinematic>
         </link>
         <link name="arm_link_3">
            <pose>0.272845 -0.018663 0.226506 -6.21005e-16 1.41372 2.96706</pose>
            <inertial>
               <pose>0.0001 0.0967 0.02107 0 -0 0</pose>
               <inertia>
                  <ixx>0.002459</ixx>
                  <ixy>0</ixy>
                  <ixz>0</ixz>
                  <iyy>0.002571</iyy>
                  <iyz>-0</iyz>
                  <izz>0.000535</izz>
               </inertia>
               <mass>0.934</mass>
            </inertial>
            <collision name="arm_link_3_geom">
               <pose>0 0.028 0.079 0 -0 0</pose>
               <geometry>
                  <mesh>
                     <uri>model://youbot/meshes/arm/arm3_convex.stl</uri>
                  </mesh>
               </geometry>
               <surface>
                  <friction>
                     <ode>
                        <mu>0</mu>
                        <mu2>0</mu2>
                        <fdir1>0 0 0</fdir1>
                        <slip1>0</slip1>
                        <slip2>0</slip2>
                     </ode>
                  </friction>
                  <bounce>
                     <restitution_coefficient>0</restitution_coefficient>
                     <threshold>0</threshold>
                  </bounce>
                  <contact>
                     <ode>
                        <soft_cfm>0</soft_cfm>
                        <soft_erp>0.2</soft_erp>
                        <kp>1e+13</kp>
                        <kd>1e+11</kd>
                        <max_vel>-1</max_vel>
                        <min_depth>0</min_depth>
                     </ode>
                  </contact>
               </surface>
               <laser_retro>0</laser_retro>
               <max_contacts>10</max_contacts>
            </collision>
            <visual name="arm_link_3_geom_visual">
               <pose>0 0.028 0.079 0 -0 0</pose>
               <geometry>
                  <mesh>
                     <uri>model://youbot/meshes/arm/arm3.dae</uri>
                  </mesh>
               </geometry>
            </visual>
            <gravity>1</gravity>
            <self_collide>0</self_collide>
            <kinematic>0</kinematic>
         </link>
         <link name="arm_link_4">
            <pose>0.141533 0.004491 0.247624 0 -0.375246 2.96706</pose>
            <inertial>
               <pose>0.00011 0.05103 -0.02319 0 -0 0</pose>
               <inertia>
                  <ixx>0.000869</ixx>
                  <ixy>0</ixy>
                  <ixz>-0</ixz>
                  <iyy>0.001173</iyy>
                  <iyz>-0.000231</iyz>
                  <izz>0.001091</izz>
               </inertia>
               <mass>0.877</mass>
            </inertial>
            <collision name="arm_link_4_geom">
               <pose>0 -0.01 0.029 0 -0 0</pose>
               <geometry>
                  <mesh>
                     <uri>model://youbot/meshes/arm/arm4_convex.stl</uri>
                  </mesh>
               </geometry>
               <surface>
                  <friction>
                     <ode>
                        <mu>0</mu>
                        <mu2>0</mu2>
                        <fdir1>0 0 0</fdir1>
                        <slip1>0</slip1>
                        <slip2>0</slip2>
                     </ode>
                  </friction>
                  <bounce>
                     <restitution_coefficient>0</restitution_coefficient>
                     <threshold>0</threshold>
                  </bounce>
                  <contact>
                     <ode>
                        <soft_cfm>0</soft_cfm>
                        <soft_erp>0.2</soft_erp>
                        <kp>1e+13</kp>
                        <kd>1e+11</kd>
                        <max_vel>-1</max_vel>
                        <min_depth>0</min_depth>
                     </ode>
                  </contact>
               </surface>
               <laser_retro>0</laser_retro>
               <max_contacts>10</max_contacts>
            </collision>
            <visual name="arm_link_4_geom_visual">
               <pose>0 -0.01 0.029 0 -0 0</pose>
               <geometry>
                  <mesh>
                     <uri>model://youbot/meshes/arm/arm4.dae</uri>
                  </mesh>
               </geometry>
            </visual>
            <gravity>1</gravity>
            <self_collide>0</self_collide>
            <kinematic>0</kinematic>
         </link>
         <link name="arm_link_5">
            <pose>0.190287 -0.004106 0.367846 -0.085052 0.365926 -0.408445</pose>
            <inertial>
               <pose>0 0.00115 -0.01683 0 -0 0</pose>
               <inertia>
                  <ixx>0.00028</ixx>
                  <ixy>0</ixy>
                  <ixz>0</ixz>
                  <iyy>0.000339</iyy>
                  <iyz>0</iyz>
                  <izz>0.000119</izz>
               </inertia>
               <mass>0.251</mass>
            </inertial>
            <collision name="arm_link_5_geom">
               <pose>0.003 0 -0.034 0 -0 0</pose>
               <geometry>
                  <mesh>
                     <uri>model://youbot/meshes/arm/arm5_convex.stl</uri>
                  </mesh>
               </geometry>
               <surface>
                  <friction>
                     <ode>
                        <mu>0</mu>
                        <mu2>0</mu2>
                        <fdir1>0 0 0</fdir1>
                        <slip1>0</slip1>
                        <slip2>0</slip2>
                     </ode>
                  </friction>
                  <bounce>
                     <restitution_coefficient>0</restitution_coefficient>
                     <threshold>0</threshold>
                  </bounce>
                  <contact>
                     <ode>
                        <soft_cfm>0</soft_cfm>
                        <soft_erp>0.2</soft_erp>
                        <kp>1e+13</kp>
                        <kd>1e+11</kd>
                        <max_vel>-1</max_vel>
                        <min_depth>0</min_depth>
                     </ode>
                  </contact>
               </surface>
               <laser_retro>0</laser_retro>
               <max_contacts>10</max_contacts>
            </collision>
            <visual name="arm_link_5_geom_visual">
               <pose>0.003 0 -0.034 0 -0 0</pose>
               <geometry>
                  <mesh>
                     <uri>model://youbot/meshes/arm/arm5.dae</uri>
                  </mesh>
               </geometry>
            </visual>
            <gravity>1</gravity>
            <self_collide>0</self_collide>
            <kinematic>0</kinematic>
         </link>
         <link name="gripper_palm_link">
            <pose>0.190287 -0.004106 0.367846 -0.085052 0.365926 -0.408445</pose>
            <inertial>
               <pose>0 0 0 0 -0 0</pose>
               <inertia>
                  <ixx>0.01</ixx>
                  <ixy>0</ixy>
                  <ixz>0</ixz>
                  <iyy>0.01</iyy>
                  <iyz>0</iyz>
                  <izz>0.01</izz>
               </inertia>
               <mass>0.1</mass>
            </inertial>
            <collision name="gripper_palm_link_geom">
               <pose>0 0 0 0 -0 0</pose>
               <geometry>
                  <mesh>
                     <uri>model://youbot/meshes/gripper/palm_convex.stl</uri>
                  </mesh>
               </geometry>
               <surface>
                  <friction>
                     <ode>
                        <mu>0</mu>
                        <mu2>0</mu2>
                        <fdir1>0 0 0</fdir1>
                        <slip1>0</slip1>
                        <slip2>0</slip2>
                     </ode>
                  </friction>
                  <bounce>
                     <restitution_coefficient>0</restitution_coefficient>
                     <threshold>0</threshold>
                  </bounce>
                  <contact>
                     <ode>
                        <soft_cfm>0</soft_cfm>
                        <soft_erp>0.2</soft_erp>
                        <kp>1e+13</kp>
                        <kd>1e+11</kd>
                        <max_vel>-1</max_vel>
                        <min_depth>0</min_depth>
                     </ode>
                  </contact>
               </surface>
               <laser_retro>0</laser_retro>
               <max_contacts>10</max_contacts>
            </collision>
            <visual name="gripper_palm_link_geom_visual">
               <pose>0 0 0 0 -0 0</pose>
               <geometry>
                  <mesh>
                     <uri>model://youbot/meshes/gripper/palm.stl</uri>
                  </mesh>
               </geometry>
               <material>
                  <script>
                     <uri>file://media/materials/scripts/gazebo.material</uri>
                     <name>Gazebo/Black</name>
                  </script>
               </material>
            </visual>
            <gravity>1</gravity>
            <self_collide>1</self_collide>
            <kinematic>0</kinematic>
         </link>
         <link name="gripper_finger_link_l">
            <pose>0.21326 -0.001105 0.408579 0.085052 -0.365926 2.73315</pose>
            <inertial>
               <pose>0 -0.001 0 0 -0 0</pose>
               <inertia>
                  <ixx>0.01</ixx>
                  <ixy>0</ixy>
                  <ixz>0</ixz>
                  <iyy>0.01</iyy>
                  <iyz>0</iyz>
                  <izz>0.01</izz>
               </inertia>
               <mass>0.01</mass>
            </inertial>
            <collision name="gripper_finger_link_l_geom">
               <pose>0 0 0 0 -0 0</pose>
               <geometry>
                  <mesh>
                     <uri>model://youbot/meshes/gripper/finger_convex.stl</uri>
                  </mesh>
               </geometry>
               <surface>
                  <friction>
                     <ode>
                        <mu>0</mu>
                        <mu2>0</mu2>
                        <fdir1>0 0 0</fdir1>
                        <slip1>0</slip1>
                        <slip2>0</slip2>
                     </ode>
                  </friction>
                  <bounce>
                     <restitution_coefficient>0</restitution_coefficient>
                     <threshold>0</threshold>
                  </bounce>
                  <contact>
                     <ode>
                        <soft_cfm>0</soft_cfm>
                        <soft_erp>0.2</soft_erp>
                        <kp>1e+13</kp>
                        <kd>1e+11</kd>
                        <max_vel>-1</max_vel>
                        <min_depth>0</min_depth>
                     </ode>
                  </contact>
               </surface>
               <laser_retro>0</laser_retro>
               <max_contacts>10</max_contacts>
            </collision>
            <visual name="gripper_finger_link_l_geom_visual">
               <pose>0 0 0 0 -0 0</pose>
               <geometry>
                  <mesh>
                     <uri>model://youbot/meshes/gripper/finger.stl</uri>
                  </mesh>
               </geometry>
            </visual>
            <gravity>1</gravity>
            <self_collide>0</self_collide>
            <kinematic>0</kinematic>
         </link>
         <link name="gripper_finger_link_r">
            <pose>0.207375 -0.015929 0.409848 -0.085052 0.365926 -0.408445</pose>
            <inertial>
               <pose>0 -0.001 0 0 -0 0</pose>
               <inertia>
                  <ixx>0.01</ixx>
                  <ixy>0</ixy>
                  <ixz>0</ixz>
                  <iyy>0.01</iyy>
                  <iyz>0</iyz>
                  <izz>0.01</izz>
               </inertia>
               <mass>0.01</mass>
            </inertial>
            <collision name="gripper_finger_link_r_geom">
               <pose>0 0 0 0 -0 0</pose>
               <geometry>
                  <mesh>
                     <uri>model://youbot/meshes/gripper/finger_convex.stl</uri>
                  </mesh>
               </geometry>
               <surface>
                  <friction>
                     <ode>
                        <mu>0</mu>
                        <mu2>0</mu2>
                        <fdir1>0 0 0</fdir1>
                        <slip1>0</slip1>
                        <slip2>0</slip2>
                     </ode>
                  </friction>
                  <bounce>
                     <restitution_coefficient>0</restitution_coefficient>
                     <threshold>0</threshold>
                  </bounce>
                  <contact>
                     <ode>
                        <soft_cfm>0</soft_cfm>
                        <soft_erp>0.2</soft_erp>
                        <kp>1e+13</kp>
                        <kd>1e+11</kd>
                        <max_vel>-1</max_vel>
                        <min_depth>0</min_depth>
                     </ode>
                  </contact>
               </surface>
               <laser_retro>0</laser_retro>
               <max_contacts>10</max_contacts>
            </collision>
            <visual name="gripper_finger_link_r_geom_visual">
               <pose>0 0 0 0 -0 0</pose>
               <geometry>
                  <mesh>
                     <uri>model://youbot/meshes/gripper/finger.stl</uri>
                  </mesh>
               </geometry>
            </visual>
            <gravity>1</gravity>
            <self_collide>0</self_collide>
            <kinematic>0</kinematic>
         </link>
         <link name="base_laser_front_link">
            <pose>0.3 0 -0.03 0 -0 0</pose>
            <inertial>
               <pose>0 0 0 0 -0 0</pose>
               <inertia>
                  <ixx>0.1</ixx>
                  <ixy>0</ixy>
                  <ixz>0</ixz>
                  <iyy>0.1</iyy>
                  <iyz>0</iyz>
                  <izz>0.1</izz>
               </inertia>
               <mass>0.16</mass>
            </inertial>
            <collision name="base_laser_front_link_geom">
               <pose>0 0 0 0 -0 0</pose>
               <geometry>
                  <mesh>
                     <uri>model://hokuyo/meshes/hokuyo_convex.stl</uri>
                  </mesh>
               </geometry>
               <surface>
                  <friction>
                     <ode>
                        <mu>0</mu>
                        <mu2>0</mu2>
                        <fdir1>0 0 0</fdir1>
                        <slip1>0</slip1>
                        <slip2>0</slip2>
                     </ode>
                  </friction>
                  <bounce>
                     <restitution_coefficient>0</restitution_coefficient>
                     <threshold>0</threshold>
                  </bounce>
                  <contact>
                     <ode>
                        <soft_cfm>0</soft_cfm>
                        <soft_erp>0.2</soft_erp>
                        <kp>1e+13</kp>
                        <kd>1e+11</kd>
                        <max_vel>-1</max_vel>
                        <min_depth>0</min_depth>
                     </ode>
                  </contact>
               </surface>
               <laser_retro>0</laser_retro>
               <max_contacts>10</max_contacts>
            </collision>
            <visual name="base_laser_front_link_geom_visual">
               <pose>0 0 0 0 -0 0</pose>
               <geometry>
                  <mesh>
                     <uri>model://hokuyo/meshes/hokuyo.dae</uri>
                  </mesh>
               </geometry>
            </visual>
            <sensor name="base_laser_front" type="ray">
               <pose>0 0 0 0 -0 0</pose>
               <ray>
                  <scan>
                     <horizontal>
                        <samples>640</samples>
                        <resolution>1</resolution>
                        <min_angle>-1.57</min_angle>
                        <max_angle>1.57</max_angle>
                     </horizontal>
                  </scan>
                  <range>
                     <min>0.05</min>
                     <max>5.6</max>
                     <resolution>0.36</resolution>
                  </range>
               </ray>
               <always_on>0</always_on>
               <update_rate>10</update_rate>
               <visualize>0</visualize>
            </sensor>
            <gravity>1</gravity>
            <self_collide>0</self_collide>
            <kinematic>0</kinematic>
         </link>
         <link name="caster_link_bl">
            <pose>-0.228 0.158 -0.034 0 -0 0</pose>
            <inertial>
               <pose>0 0 0 0 -0 0</pose>
               <inertia>
                  <ixx>0.012412</ixx>
                  <ixy>-0.000712</ixy>
                  <ixz>0.000503</ixz>
                  <iyy>0.015218</iyy>
                  <iyz>-4e-06</iyz>
                  <izz>0.011764</izz>
               </inertia>
               <mass>0.1</mass>
            </inertial>
            <gravity>1</gravity>
            <self_collide>0</self_collide>
            <kinematic>0</kinematic>
         </link>
         <link name="wheel_link_bl">
            <pose>-0.228 0.158 -0.034 0 -0 0</pose>
            <inertial>
               <pose>0 0 0 0 -0 0</pose>
               <inertia>
                  <ixx>0.012412</ixx>
                  <ixy>-0.000712</ixy>
                  <ixz>0.000503</ixz>
                  <iyy>0.015218</iyy>
                  <iyz>-4e-06</iyz>
                  <izz>0.011764</izz>
               </inertia>
               <mass>0.4</mass>
            </inertial>
            <collision name="wheel_link_bl_geom">
               <pose>0 0 0 1.5708 -0 0</pose>
               <geometry>
                  <cylinder>
                     <radius>0.05</radius>
                     <length>0.005</length>
                  </cylinder>
               </geometry>
               <surface>
                  <friction>
                     <ode>
                        <mu>0</mu>
                        <mu2>0</mu2>
                        <fdir1>0 0 0</fdir1>
                        <slip1>0</slip1>
                        <slip2>0</slip2>
                     </ode>
                  </friction>
                  <bounce>
                     <restitution_coefficient>0</restitution_coefficient>
                     <threshold>0</threshold>
                  </bounce>
                  <contact>
                     <ode>
                        <soft_cfm>0</soft_cfm>
                        <soft_erp>0.2</soft_erp>
                        <kp>1e+13</kp>
                        <kd>1e+11</kd>
                        <max_vel>-1</max_vel>
                        <min_depth>0</min_depth>
                     </ode>
                  </contact>
               </surface>
               <laser_retro>0</laser_retro>
               <max_contacts>10</max_contacts>
            </collision>
            <visual name="wheel_link_bl_geom_visual">
               <pose>0 0 0 0 -0 0</pose>
               <geometry>
                  <mesh>
                     <uri>model://youbot/meshes/base/back-left_wheel.dae</uri>
                  </mesh>
               </geometry>
               <material>
                  <script>
                     <uri>model://youbot/materials/scripts/youbot.material</uri>
                     <name>youbot/Orange</name>
                  </script>
               </material>
            </visual>
            <gravity>1</gravity>
            <self_collide>0</self_collide>
            <kinematic>0</kinematic>
         </link>
         <link name="caster_link_br">
            <pose>-0.228 -0.158 -0.034 0 -0 0</pose>
            <inertial>
               <pose>0 0 0 0 -0 0</pose>
               <inertia>
                  <ixx>0.012412</ixx>
                  <ixy>-0.000712</ixy>
                  <ixz>0.000503</ixz>
                  <iyy>0.015218</iyy>
                  <iyz>-4e-06</iyz>
                  <izz>0.011764</izz>
               </inertia>
               <mass>0.1</mass>
            </inertial>
            <gravity>1</gravity>
            <self_collide>0</self_collide>
            <kinematic>0</kinematic>
         </link>
         <link name="wheel_link_br">
            <pose>-0.228 -0.158 -0.034 0 -0 0</pose>
            <inertial>
               <pose>0 0 0 0 -0 0</pose>
               <inertia>
                  <ixx>0.012412</ixx>
                  <ixy>-0.000712</ixy>
                  <ixz>0.000503</ixz>
                  <iyy>0.015218</iyy>
                  <iyz>-4e-06</iyz>
                  <izz>0.011764</izz>
               </inertia>
               <mass>0.4</mass>
            </inertial>
            <collision name="wheel_link_br_geom">
               <pose>0 0 0 1.5708 -0 0</pose>
               <geometry>
                  <cylinder>
                     <radius>0.05</radius>
                     <length>0.005</length>
                  </cylinder>
               </geometry>
               <surface>
                  <friction>
                     <ode>
                        <mu>0</mu>
                        <mu2>0</mu2>
                        <fdir1>0 0 0</fdir1>
                        <slip1>0</slip1>
                        <slip2>0</slip2>
                     </ode>
                  </friction>
                  <bounce>
                     <restitution_coefficient>0</restitution_coefficient>
                     <threshold>0</threshold>
                  </bounce>
                  <contact>
                     <ode>
                        <soft_cfm>0</soft_cfm>
                        <soft_erp>0.2</soft_erp>
                        <kp>1e+13</kp>
                        <kd>1e+11</kd>
                        <max_vel>-1</max_vel>
                        <min_depth>0</min_depth>
                     </ode>
                  </contact>
               </surface>
               <laser_retro>0</laser_retro>
               <max_contacts>10</max_contacts>
            </collision>
            <visual name="wheel_link_br_geom_visual">
               <pose>0 0 0 0 -0 0</pose>
               <geometry>
                  <mesh>
                     <uri>model://youbot/meshes/base/back-right_wheel.dae</uri>
                  </mesh>
               </geometry>
               <material>
                  <script>
                     <uri>model://youbot/materials/scripts/youbot.material</uri>
                     <name>youbot/Orange</name>
                  </script>
               </material>
            </visual>
            <gravity>1</gravity>
            <self_collide>0</self_collide>
            <kinematic>0</kinematic>
         </link>
         <link name="caster_link_fl">
            <pose>0.228 0.158 -0.034 0 -0 0</pose>
            <inertial>
               <pose>0 0 0 0 -0 0</pose>
               <inertia>
                  <ixx>0.012412</ixx>
                  <ixy>-0.000712</ixy>
                  <ixz>0.000503</ixz>
                  <iyy>0.015218</iyy>
                  <iyz>-4e-06</iyz>
                  <izz>0.011764</izz>
               </inertia>
               <mass>0.1</mass>
            </inertial>
            <gravity>1</gravity>
            <self_collide>0</self_collide>
            <kinematic>0</kinematic>
         </link>
         <link name="wheel_link_fl">
            <pose>0.228 0.158 -0.034 0 -0 0</pose>
            <inertial>
               <pose>0 0 0 0 -0 0</pose>
               <inertia>
                  <ixx>0.012412</ixx>
                  <ixy>-0.000712</ixy>
                  <ixz>0.000503</ixz>
                  <iyy>0.015218</iyy>
                  <iyz>-4e-06</iyz>
                  <izz>0.011764</izz>
               </inertia>
               <mass>0.4</mass>
            </inertial>
            <collision name="wheel_link_fl_geom">
               <pose>0 0 0 1.5708 -0 0</pose>
               <geometry>
                  <cylinder>
                     <radius>0.05</radius>
                     <length>0.005</length>
                  </cylinder>
               </geometry>
               <surface>
                  <friction>
                     <ode>
                        <mu>0</mu>
                        <mu2>0</mu2>
                        <fdir1>0 0 0</fdir1>
                        <slip1>0</slip1>
                        <slip2>0</slip2>
                     </ode>
                  </friction>
                  <bounce>
                     <restitution_coefficient>0</restitution_coefficient>
                     <threshold>0</threshold>
                  </bounce>
                  <contact>
                     <ode>
                        <soft_cfm>0</soft_cfm>
                        <soft_erp>0.2</soft_erp>
                        <kp>1e+13</kp>
                        <kd>1e+11</kd>
                        <max_vel>-1</max_vel>
                        <min_depth>0</min_depth>
                     </ode>
                  </contact>
               </surface>
               <laser_retro>0</laser_retro>
               <max_contacts>10</max_contacts>
            </collision>
            <visual name="wheel_link_fl_geom_visual">
               <pose>0 0 0 0 -0 0</pose>
               <geometry>
                  <mesh>
                     <uri>model://youbot/meshes/base/front-left_wheel.dae</uri>
                  </mesh>
               </geometry>
               <material>
                  <script>
                     <uri>model://youbot/materials/scripts/youbot.material</uri>
                     <name>youbot/Orange</name>
                  </script>
               </material>
            </visual>
            <gravity>1</gravity>
            <self_collide>0</self_collide>
            <kinematic>0</kinematic>
         </link>
         <link name="caster_link_fr">
            <pose>0.228 -0.158 -0.034 0 -0 0</pose>
            <inertial>
               <pose>0 0 0 0 -0 0</pose>
               <inertia>
                  <ixx>0.012412</ixx>
                  <ixy>-0.000712</ixy>
                  <ixz>0.000503</ixz>
                  <iyy>0.015218</iyy>
                  <iyz>-4e-06</iyz>
                  <izz>0.011764</izz>
               </inertia>
               <mass>0.1</mass>
            </inertial>
            <gravity>1</gravity>
            <self_collide>0</self_collide>
            <kinematic>0</kinematic>
         </link>
         <link name="wheel_link_fr">
            <pose>0.228 -0.158 -0.034 0 -0 0</pose>
            <inertial>
               <pose>0 0 0 0 -0 0</pose>
               <inertia>
                  <ixx>0.012412</ixx>
                  <ixy>-0.000712</ixy>
                  <ixz>0.000503</ixz>
                  <iyy>0.015218</iyy>
                  <iyz>-4e-06</iyz>
                  <izz>0.011764</izz>
               </inertia>
               <mass>0.4</mass>
            </inertial>
            <collision name="wheel_link_fr_geom">
               <pose>0 0 0 1.5708 -0 0</pose>
               <geometry>
                  <cylinder>
                     <radius>0.05</radius>
                     <length>0.005</length>
                  </cylinder>
               </geometry>
               <surface>
                  <friction>
                     <ode>
                        <mu>0</mu>
                        <mu2>0</mu2>
                        <fdir1>0 0 0</fdir1>
                        <slip1>0</slip1>
                        <slip2>0</slip2>
                     </ode>
                  </friction>
                  <bounce>
                     <restitution_coefficient>0</restitution_coefficient>
                     <threshold>0</threshold>
                  </bounce>
                  <contact>
                     <ode>
                        <soft_cfm>0</soft_cfm>
                        <soft_erp>0.2</soft_erp>
                        <kp>1e+13</kp>
                        <kd>1e+11</kd>
                        <max_vel>-1</max_vel>
                        <min_depth>0</min_depth>
                     </ode>
                  </contact>
               </surface>
               <laser_retro>0</laser_retro>
               <max_contacts>10</max_contacts>
            </collision>
            <visual name="wheel_link_fr_geom_visual">
               <pose>0 0 0 0 -0 0</pose>
               <geometry>
                  <mesh>
                     <uri>model://youbot/meshes/base/front-right_wheel.dae</uri>
                  </mesh>
               </geometry>
               <material>
                  <script>
                     <uri>model://youbot/materials/scripts/youbot.material</uri>
                     <name>youbot/Orange</name>
                  </script>
               </material>
            </visual>
            <gravity>1</gravity>
            <self_collide>0</self_collide>
            <kinematic>0</kinematic>
         </link>
         <link name="plate_link">
            <pose>-0.159 0 0.046 0 -0 0</pose>
            <inertial>
               <pose>0 0 0 0 -0 0</pose>
               <inertia>
                  <ixx>0.01</ixx>
                  <ixy>0</ixy>
                  <ixz>0</ixz>
                  <iyy>0.01</iyy>
                  <iyz>0</iyz>
                  <izz>0.01</izz>
               </inertia>
               <mass>1</mass>
            </inertial>
            <collision name="plate_link_geom">
               <pose>0 0 0 0 -0 0</pose>
               <geometry>
                  <mesh>
                     <uri>model://youbot/meshes/plate/plate_convex.stl</uri>
                  </mesh>
               </geometry>
               <surface>
                  <friction>
                     <ode>
                        <mu>0</mu>
                        <mu2>0</mu2>
                        <fdir1>0 0 0</fdir1>
                        <slip1>0</slip1>
                        <slip2>0</slip2>
                     </ode>
                  </friction>
                  <bounce>
                     <restitution_coefficient>0</restitution_coefficient>
                     <threshold>0</threshold>
                  </bounce>
                  <contact>
                     <ode>
                        <soft_cfm>0</soft_cfm>
                        <soft_erp>0.2</soft_erp>
                        <kp>1e+13</kp>
                        <kd>1e+11</kd>
                        <max_vel>-1</max_vel>
                        <min_depth>0</min_depth>
                     </ode>
                  </contact>
               </surface>
               <laser_retro>0</laser_retro>
               <max_contacts>10</max_contacts>
            </collision>
            <visual name="plate_link_geom_visual">
               <pose>0 0 0 0 -0 0</pose>
               <geometry>
                  <mesh>
                     <uri>model://youbot/meshes/plate/plate.dae</uri>
                  </mesh>
               </geometry>
            </visual>
            <gravity>1</gravity>
            <self_collide>0</self_collide>
            <kinematic>0</kinematic>
         </link>
         <joint name="base_footprint_joint" type="revolute">
            <pose>0 0 0 0 -0 0</pose>
            <parent>base_footprint</parent>
            <child>base_link</child>
            <axis>
               <dynamics>
                  <damping>0</damping>
                  <friction>0</friction>
                  <spring_reference>0</spring_reference>
                  <spring_stiffness>0</spring_stiffness>
               </dynamics>
               <limit>
                  <lower>0</lower>
                  <upper>0</upper>
                  <effort>0</effort>
                  <velocity>0</velocity>
               </limit>
               <xyz>0 0 1</xyz>
               <use_parent_model_frame>1</use_parent_model_frame>
            </axis>
         </joint>
         <joint name="arm_joint_0" type="revolute">
            <pose>0 0 0 0 -0 0</pose>
            <parent>base_link</parent>
            <child>arm_link_0</child>
            <axis>
               <dynamics>
                  <damping>0</damping>
                  <friction>0</friction>
                  <spring_reference>0</spring_reference>
                  <spring_stiffness>0</spring_stiffness>
               </dynamics>
               <limit>
                  <lower>0</lower>
                  <upper>0</upper>
                  <effort>0</effort>
                  <velocity>0</velocity>
               </limit>
               <xyz>0 0 1</xyz>
               <use_parent_model_frame>1</use_parent_model_frame>
            </axis>
         </joint>
         <joint name="arm_joint_1" type="revolute">
            <pose>0 0 0 0 -0 0</pose>
            <parent>arm_link_0</parent>
            <child>arm_link_1</child>
            <axis>
               <dynamics>
                  <damping>1</damping>
                  <friction>0</friction>
                  <spring_reference>0</spring_reference>
                  <spring_stiffness>0</spring_stiffness>
               </dynamics>
               <limit>
                  <lower>0</lower>
                  <upper>5.89921</upper>
                  <effort>0</effort>
                  <velocity>0</velocity>
               </limit>
               <xyz>0 0 -1</xyz>
               <use_parent_model_frame>1</use_parent_model_frame>
            </axis>
         </joint>
         <joint name="arm_joint_2" type="revolute">
            <pose>0 0 0 0 -0 0</pose>
            <parent>arm_link_1</parent>
            <child>arm_link_2</child>
            <axis>
               <dynamics>
                  <damping>1</damping>
                  <friction>0</friction>
                  <spring_reference>0</spring_reference>
                  <spring_stiffness>0</spring_stiffness>
               </dynamics>
               <limit>
                  <lower>0</lower>
                  <upper>2.70526</upper>
                  <effort>0</effort>
                  <velocity>0</velocity>
               </limit>
               <xyz>-0.173648 -0.984808 0</xyz>
               <use_parent_model_frame>1</use_parent_model_frame>
            </axis>
         </joint>
         <joint name="arm_joint_3" type="revolute">
            <pose>0 0 0 0 -0 0</pose>
            <parent>arm_link_2</parent>
            <child>arm_link_3</child>
            <axis>
               <dynamics>
                  <damping>1</damping>
                  <friction>0</friction>
                  <spring_reference>0</spring_reference>
                  <spring_stiffness>0</spring_stiffness>
               </dynamics>
               <limit>
                  <lower>-5.18363</lower>
                  <upper>0</upper>
                  <effort>0</effort>
                  <velocity>0</velocity>
               </limit>
               <xyz>-0.173648 -0.984808 0</xyz>
               <use_parent_model_frame>1</use_parent_model_frame>
            </axis>
         </joint>
         <joint name="arm_joint_4" type="revolute">
            <pose>0 0 0 0 -0 0</pose>
            <parent>arm_link_3</parent>
            <child>arm_link_4</child>
            <axis>
               <dynamics>
                  <damping>1</damping>
                  <friction>0</friction>
                  <spring_reference>0</spring_reference>
                  <spring_stiffness>0</spring_stiffness>
               </dynamics>
               <limit>
                  <lower>0</lower>
                  <upper>3.57793</upper>
                  <effort>0</effort>
                  <velocity>0</velocity>
               </limit>
               <xyz>-0.173648 -0.984808 0</xyz>
               <use_parent_model_frame>1</use_parent_model_frame>
            </axis>
         </joint>
         <joint name="arm_joint_5" type="revolute">
            <pose>0 0 0 0 -0 0</pose>
            <parent>arm_link_4</parent>
            <child>arm_link_5</child>
            <axis>
               <dynamics>
                  <damping>1</damping>
                  <friction>0</friction>
                  <spring_reference>0</spring_reference>
                  <spring_stiffness>0</spring_stiffness>
               </dynamics>
               <limit>
                  <lower>0</lower>
                  <upper>5.84685</upper>
                  <effort>0</effort>
                  <velocity>0</velocity>
               </limit>
               <xyz>-0.360933 0.063642 -0.930418</xyz>
               <use_parent_model_frame>1</use_parent_model_frame>
            </axis>
         </joint>
         <joint name="gripper_palm_joint" type="revolute">
            <pose>0 0 0 0 -0 0</pose>
            <parent>arm_link_5</parent>
            <child>gripper_palm_link</child>
            <axis>
               <dynamics>
                  <damping>0</damping>
                  <friction>0</friction>
                  <spring_reference>0</spring_reference>
                  <spring_stiffness>0</spring_stiffness>
               </dynamics>
               <limit>
                  <lower>0</lower>
                  <upper>0</upper>
                  <effort>0</effort>
                  <velocity>0</velocity>
               </limit>
               <xyz>0 0 1</xyz>
               <use_parent_model_frame>1</use_parent_model_frame>
            </axis>
         </joint>
         <joint name="gripper_finger_joint_l" type="prismatic">
            <pose>0 0 0 0 -0 0</pose>
            <parent>gripper_palm_link</parent>
            <child>gripper_finger_link_l</child>
            <axis>
               <dynamics>
                  <damping>1</damping>
                  <friction>0</friction>
                  <spring_reference>0</spring_reference>
                  <spring_stiffness>0</spring_stiffness>
               </dynamics>
               <limit>
                  <lower>0</lower>
                  <upper>0.0115</upper>
                  <effort>0</effort>
                  <velocity>0</velocity>
               </limit>
               <xyz>0.367852 0.926495 -0.079325</xyz>
               <use_parent_model_frame>1</use_parent_model_frame>
            </axis>
         </joint>
         <joint name="gripper_finger_joint_r" type="prismatic">
            <pose>0 0 0 0 -0 0</pose>
            <parent>gripper_palm_link</parent>
            <child>gripper_finger_link_r</child>
            <axis>
               <dynamics>
                  <damping>1</damping>
                  <friction>0</friction>
                  <spring_reference>0</spring_reference>
                  <spring_stiffness>0</spring_stiffness>
               </dynamics>
               <limit>
                  <lower>0</lower>
                  <upper>0.0115</upper>
                  <effort>0</effort>
                  <velocity>0</velocity>
               </limit>
               <xyz>-0.367852 -0.926495 0.079325</xyz>
               <use_parent_model_frame>1</use_parent_model_frame>
            </axis>
         </joint>
         <joint name="base_laser_front_hokuyo_urg04_laser_joint" type="revolute">
            <pose>0 0 0 0 -0 0</pose>
            <parent>base_link</parent>
            <child>base_laser_front_link</child>
            <axis>
               <dynamics>
                  <damping>0</damping>
                  <friction>0</friction>
                  <spring_reference>0</spring_reference>
                  <spring_stiffness>0</spring_stiffness>
               </dynamics>
               <limit>
                  <lower>0</lower>
                  <upper>0</upper>
                  <effort>0</effort>
                  <velocity>0</velocity>
               </limit>
               <xyz>0 0 1</xyz>
               <use_parent_model_frame>1</use_parent_model_frame>
            </axis>
         </joint>
         <joint name="caster_joint_bl" type="revolute">
            <pose>0 0 0 0 -0 0</pose>
            <parent>base_link</parent>
            <child>caster_link_bl</child>
            <axis>
               <dynamics>
                  <damping>1</damping>
                  <friction>0</friction>
                  <spring_reference>0</spring_reference>
                  <spring_stiffness>0</spring_stiffness>
               </dynamics>
               <limit>
                  <lower>-1e+16</lower>
                  <upper>1e+16</upper>
                  <effort>0</effort>
                  <velocity>0</velocity>
               </limit>
               <xyz>0 0 1</xyz>
               <use_parent_model_frame>1</use_parent_model_frame>
            </axis>
         </joint>
         <joint name="wheel_joint_bl" type="revolute">
            <pose>0 0 0 0 -0 0</pose>
            <parent>caster_link_bl</parent>
            <child>wheel_link_bl</child>
            <axis>
               <dynamics>
                  <damping>1</damping>
                  <friction>0</friction>
                  <spring_reference>0</spring_reference>
                  <spring_stiffness>0</spring_stiffness>
               </dynamics>
               <limit>
                  <lower>-1e+16</lower>
                  <upper>1e+16</upper>
                  <effort>0</effort>
                  <velocity>0</velocity>
               </limit>
               <xyz>0 1 0</xyz>
               <use_parent_model_frame>1</use_parent_model_frame>
            </axis>
         </joint>
         <joint name="caster_joint_br" type="revolute">
            <pose>0 0 0 0 -0 0</pose>
            <parent>base_link</parent>
            <child>caster_link_br</child>
            <axis>
               <dynamics>
                  <damping>1</damping>
                  <friction>0</friction>
                  <spring_reference>0</spring_reference>
                  <spring_stiffness>0</spring_stiffness>
               </dynamics>
               <limit>
                  <lower>-1e+16</lower>
                  <upper>1e+16</upper>
                  <effort>0</effort>
                  <velocity>0</velocity>
               </limit>
               <xyz>0 0 1</xyz>
               <use_parent_model_frame>1</use_parent_model_frame>
            </axis>
         </joint>
         <joint name="wheel_joint_br" type="revolute">
            <pose>0 0 0 0 -0 0</pose>
            <parent>caster_link_br</parent>
            <child>wheel_link_br</child>
            <axis>
               <dynamics>
                  <damping>1</damping>
                  <friction>0</friction>
                  <spring_reference>0</spring_reference>
                  <spring_stiffness>0</spring_stiffness>
               </dynamics>
               <limit>
                  <lower>-1e+16</lower>
                  <upper>1e+16</upper>
                  <effort>0</effort>
                  <velocity>0</velocity>
               </limit>
               <xyz>0 1 0</xyz>
               <use_parent_model_frame>1</use_parent_model_frame>
            </axis>
         </joint>
         <joint name="caster_joint_fl" type="revolute">
            <pose>0 0 0 0 -0 0</pose>
            <parent>base_link</parent>
            <child>caster_link_fl</child>
            <axis>
               <dynamics>
                  <damping>1</damping>
                  <friction>0</friction>
                  <spring_reference>0</spring_reference>
                  <spring_stiffness>0</spring_stiffness>
               </dynamics>
               <limit>
                  <lower>-1e+16</lower>
                  <upper>1e+16</upper>
                  <effort>0</effort>
                  <velocity>0</velocity>
               </limit>
               <xyz>0 0 1</xyz>
               <use_parent_model_frame>1</use_parent_model_frame>
            </axis>
         </joint>
         <joint name="wheel_joint_fl" type="revolute">
            <pose>0 0 0 0 -0 0</pose>
            <parent>caster_link_fl</parent>
            <child>wheel_link_fl</child>
            <axis>
               <dynamics>
                  <damping>1</damping>
                  <friction>0</friction>
                  <spring_reference>0</spring_reference>
                  <spring_stiffness>0</spring_stiffness>
               </dynamics>
               <limit>
                  <lower>-1e+16</lower>
                  <upper>1e+16</upper>
                  <effort>0</effort>
                  <velocity>0</velocity>
               </limit>
               <xyz>0 1 0</xyz>
               <use_parent_model_frame>1</use_parent_model_frame>
            </axis>
         </joint>
         <joint name="caster_joint_fr" type="revolute">
            <pose>0 0 0 0 -0 0</pose>
            <parent>base_link</parent>
            <child>caster_link_fr</child>
            <axis>
               <dynamics>
                  <damping>1</damping>
                  <friction>0</friction>
                  <spring_reference>0</spring_reference>
                  <spring_stiffness>0</spring_stiffness>
               </dynamics>
               <limit>
                  <lower>-1e+16</lower>
                  <upper>1e+16</upper>
                  <effort>0</effort>
                  <velocity>0</velocity>
               </limit>
               <xyz>0 0 1</xyz>
               <use_parent_model_frame>1</use_parent_model_frame>
            </axis>
         </joint>
         <joint name="wheel_joint_fr" type="revolute">
            <pose>0 0 0 0 -0 0</pose>
            <parent>caster_link_fr</parent>
            <child>wheel_link_fr</child>
            <axis>
               <dynamics>
                  <damping>1</damping>
                  <friction>0</friction>
                  <spring_reference>0</spring_reference>
                  <spring_stiffness>0</spring_stiffness>
               </dynamics>
               <limit>
                  <lower>-1e+16</lower>
                  <upper>1e+16</upper>
                  <effort>0</effort>
                  <velocity>0</velocity>
               </limit>
               <xyz>0 1 0</xyz>
               <use_parent_model_frame>1</use_parent_model_frame>
            </axis>
         </joint>
         <joint name="plate_joint" type="revolute">
            <parent>base_link</parent>
            <child>plate_link</child>
            <axis>
               <dynamics>
                  <damping>0</damping>
                  <friction>0</friction>
                  <spring_reference>0</spring_reference>
                  <spring_stiffness>0</spring_stiffness>
               </dynamics>
               <limit>
                  <lower>0</lower>
                  <upper>0</upper>
                  <effort>0</effort>
                  <velocity>0</velocity>
               </limit>
               <xyz>0 0 1</xyz>
               <use_parent_model_frame>1</use_parent_model_frame>
            </axis>
         </joint>
         <static>0</static>
      </model>
      <model name="grey_tote">
         <link name="link">
            <inertial>
               <pose>0 0 0.14155 0 -0 0</pose>
               <mass>3.53802</mass>
               <inertia>
                  <ixx>0.0688358</ixx>
                  <ixy>0</ixy>
                  <ixz>0</ixz>
                  <iyy>0.139596</iyy>
                  <iyz>0</iyz>
                  <izz>0.155909</izz>
               </inertia>
            </inertial>
            <collision name="lid">
               <pose>0 0 0.28958 0 -0 0</pose>
               <geometry>
                  <box>
                     <size>0.67768 0.41298 0.01588</size>
                  </box>
               </geometry>
               <max_contacts>10</max_contacts>
               <surface>
                  <contact>
                     <ode />
                  </contact>
                  <bounce />
                  <friction>
                     <ode />
                  </friction>
               </surface>
            </collision>
            <collision name="lid_lip_1">
               <pose>0 0.20063 0.3048 0 -0 0</pose>
               <geometry>
                  <box>
                     <size>0.65068 0.0105 0.0127</size>
                  </box>
               </geometry>
               <max_contacts>10</max_contacts>
               <surface>
                  <contact>
                     <ode />
                  </contact>
                  <bounce />
                  <friction>
                     <ode />
                  </friction>
               </surface>
            </collision>
            <collision name="lid_lip_2">
               <pose>0 -0.20063 0.3048 0 -0 0</pose>
               <geometry>
                  <box>
                     <size>0.65068 0.0105 0.0127</size>
                  </box>
               </geometry>
               <max_contacts>10</max_contacts>
               <surface>
                  <contact>
                     <ode />
                  </contact>
                  <bounce />
                  <friction>
                     <ode />
                  </friction>
               </surface>
            </collision>
            <collision name="lid_lip_3">
               <pose>0.32585 0 0.3048 0 -0 0</pose>
               <geometry>
                  <box>
                     <size>0.02602 0.31202 0.0127</size>
                  </box>
               </geometry>
               <max_contacts>10</max_contacts>
               <surface>
                  <contact>
                     <ode />
                  </contact>
                  <bounce />
                  <friction>
                     <ode />
                  </friction>
               </surface>
            </collision>
            <collision name="lid_lip_4">
               <pose>-0.32585 0 0.3048 0 -0 0</pose>
               <geometry>
                  <box>
                     <size>0.02602 0.31202 0.0127</size>
                  </box>
               </geometry>
               <max_contacts>10</max_contacts>
               <surface>
                  <contact>
                     <ode />
                  </contact>
                  <bounce />
                  <friction>
                     <ode />
                  </friction>
               </surface>
            </collision>
            <collision name="side_wall_1">
               <pose>0 -0.18 0.14155 0.0611474 -0 0</pose>
               <geometry>
                  <box>
                     <size>0.58404 0.02602 0.283099</size>
                  </box>
               </geometry>
               <max_contacts>10</max_contacts>
               <surface>
                  <contact>
                     <ode />
                  </contact>
                  <bounce />
                  <friction>
                     <ode />
                  </friction>
               </surface>
            </collision>
            <collision name="side_wall_2">
               <pose>0 0.18 0.14155 -0.0611474 0 0</pose>
               <geometry>
                  <box>
                     <size>0.58404 0.02602 0.283099</size>
                  </box>
               </geometry>
               <max_contacts>10</max_contacts>
               <surface>
                  <contact>
                     <ode />
                  </contact>
                  <bounce />
                  <friction>
                     <ode />
                  </friction>
               </surface>
            </collision>
            <collision name="side_wall_3">
               <pose>0.305 0 0.14155 0 0.0611474 0</pose>
               <geometry>
                  <box>
                     <size>0.02602 0.33046 0.283099</size>
                  </box>
               </geometry>
               <max_contacts>10</max_contacts>
               <surface>
                  <contact>
                     <ode />
                  </contact>
                  <bounce />
                  <friction>
                     <ode />
                  </friction>
               </surface>
            </collision>
            <collision name="side_wall_4">
               <pose>-0.305 0 0.14155 0 -0.0611474 0</pose>
               <geometry>
                  <box>
                     <size>0.02602 0.33046 0.283099</size>
                  </box>
               </geometry>
               <max_contacts>10</max_contacts>
               <surface>
                  <contact>
                     <ode />
                  </contact>
                  <bounce />
                  <friction>
                     <ode />
                  </friction>
               </surface>
            </collision>
            <collision name="bottom">
               <pose>0 0 0.01 0 -0 0</pose>
               <geometry>
                  <box>
                     <size>0.58404 0.33046 0.02</size>
                  </box>
               </geometry>
               <max_contacts>10</max_contacts>
               <surface>
                  <contact>
                     <ode />
                  </contact>
                  <bounce />
                  <friction>
                     <ode />
                  </friction>
               </surface>
            </collision>
            <collision name="corner_1">
               <pose>0.30202 -0.175 0.14155 0.0611474 0.0611474 -4.34493e-19</pose>
               <geometry>
                  <cylinder>
                     <radius>0.01268</radius>
                     <length>0.283099</length>
                  </cylinder>
               </geometry>
               <max_contacts>10</max_contacts>
               <surface>
                  <contact>
                     <ode />
                  </contact>
                  <bounce />
                  <friction>
                     <ode />
                  </friction>
               </surface>
            </collision>
            <collision name="corner_2">
               <pose>-0.30202 -0.175 0.14155 0.0611474 -0.0611474 4.34493e-19</pose>
               <geometry>
                  <cylinder>
                     <radius>0.01268</radius>
                     <length>0.283099</length>
                  </cylinder>
               </geometry>
               <max_contacts>10</max_contacts>
               <surface>
                  <contact>
                     <ode />
                  </contact>
                  <bounce />
                  <friction>
                     <ode />
                  </friction>
               </surface>
            </collision>
            <collision name="corner_3">
               <pose>-0.30202 0.175 0.14155 -0.0611474 -0.0611474 -4.34493e-19</pose>
               <geometry>
                  <cylinder>
                     <radius>0.01268</radius>
                     <length>0.283099</length>
                  </cylinder>
               </geometry>
               <max_contacts>10</max_contacts>
               <surface>
                  <contact>
                     <ode />
                  </contact>
                  <bounce />
                  <friction>
                     <ode />
                  </friction>
               </surface>
            </collision>
            <collision name="corner_4">
               <pose>0.30202 0.175 0.14155 -0.0611474 0.0611474 4.34493e-19</pose>
               <geometry>
                  <cylinder>
                     <radius>0.01268</radius>
                     <length>0.283099</length>
                  </cylinder>
               </geometry>
               <max_contacts>10</max_contacts>
               <surface>
                  <contact>
                     <ode />
                  </contact>
                  <bounce />
                  <friction>
                     <ode />
                  </friction>
               </surface>
            </collision>
            <visual name="visual">
               <geometry>
                  <mesh>
                     <uri>model://grey_tote/meshes/tote.dae</uri>
                  </mesh>
               </geometry>
            </visual>
            <self_collide>0</self_collide>
            <kinematic>0</kinematic>
            <gravity>1</gravity>
         </link>
         <pose>2 -4 0 0 -0 0</pose>
      </model>
      <state world_name="default">
         <sim_time>602 702000000</sim_time>
         <real_time>605 677064373</real_time>
         <wall_time>1431421683 366619279</wall_time>
         <model name="cafe">
            <pose>-0.562282 -2.24621 -0.182967 0 -0 0</pose>
            <link name="link">
               <pose>-0.562282 -2.24621 -0.182967 0 -0 0</pose>
               <velocity>0 0 0 0 -0 0</velocity>
               <acceleration>0 0 0 0 -0 0</acceleration>
               <wrench>0 0 0 0 -0 0</wrench>
            </link>
         </model>
         <model name="cafe_table_0">
            <pose>-2 -5 0 0 -0 0</pose>
            <link name="link">
               <pose>-2 -5 0 0 -0 0</pose>
               <velocity>0 0 0 0 -0 0</velocity>
               <acceleration>0 0 0 0 -0 0</acceleration>
               <wrench>0 0 0 0 -0 0</wrench>
            </link>
         </model>
         <model name="cafe_table_1">
            <pose>0 -7 0 0 -0 0</pose>
            <link name="link">
               <pose>0 -7 0 0 -0 0</pose>
               <velocity>0 0 0 0 -0 0</velocity>
               <acceleration>0 0 0 0 -0 0</acceleration>
               <wrench>0 0 0 0 -0 0</wrench>
            </link>
         </model>
         <model name="cafe_table_2">
            <pose>-2 -8 0 0 -0 0</pose>
            <link name="link">
               <pose>-2 -8 0 0 -0 0</pose>
               <velocity>0 0 0 0 -0 0</velocity>
               <acceleration>0 0 0 0 -0 0</acceleration>
               <wrench>0 0 0 0 -0 0</wrench>
            </link>
         </model>
         <model name="grey_tote">
            <pose>2 -4 0.007394 3e-06 1.4e-05 1e-06</pose>
            <link name="link">
               <pose>2 -4 0.007394 3e-06 1.4e-05 1e-06</pose>
               <velocity>0 0 0 0 -0 0</velocity>
               <acceleration>0 0 -9.8 0 -0 0</acceleration>
               <wrench>0 0 -34.6726 0 -0 0</wrench>
            </link>
         </model>
         <model name="ground_plane">
            <pose>0 0 0 0 -0 0</pose>
            <link name="link">
               <pose>0 0 0 0 -0 0</pose>
               <velocity>0 0 0 0 -0 0</velocity>
               <acceleration>0 0 0 0 -0 0</acceleration>
               <wrench>0 0 0 0 -0 0</wrench>
            </link>
         </model>
         <model name="husky">
            <pose>-3.66498 -9.83134 0.149586 -3e-06 -6e-06 -0.140413</pose>
            <link name="back_left_wheel">
               <pose>-3.87851 -9.51284 0.184584 -7.7e-05 1.4424 -0.140488</pose>
               <velocity>-0.005888 0.001338 0.009513 -0.007522 -0.033082 -0.00076</velocity>
               <acceleration>-1.22199 0.481378 18.9978 -0.04244 -0.038474 0.021678</acceleration>
               <wrench>-3.22079 1.26877 50.0725 0 -0 0</wrench>
            </link>
            <link name="back_right_wheel">
               <pose>-3.95842 -10.0782 0.184585 -5e-06 1.15979 -0.140418</pose>
               <velocity>-0.006924 0.001273 0.009435 -0.007189 -0.039379 -0.001292</velocity>
               <acceleration>-1.18756 0.331641 19.0085 -0.018579 -0.059397 0.005985</acceleration>
               <wrench>-3.13005 0.874105 50.1007 0 -0 0</wrench>
            </link>
            <link name="base_link">
               <pose>-3.66498 -9.83134 0.149586 -3e-06 -6e-06 -0.140413</pose>
               <velocity>-0.006626 0.00094 0.008365 0.000556 0.00426 -0.001691</velocity>
               <acceleration>0.528123 0.203791 17.5409 0.064383 0.858809 0.016084</acceleration>
               <wrench>17.8796 6.89935 593.848 0 -0 0</wrench>
            </link>
            <link name="front_left_wheel">
               <pose>-3.37155 -9.5845 0.184587 3.14159 -0.802135 3.00118</pose>
               <velocity>-0.006038 0.000541 0.007279 -0.002986 -0.033248 -0.002239</velocity>
               <acceleration>-1.19213 0.629443 14.6558 0.013589 -0.076429 -0.012797</acceleration>
               <wrench>-3.1421 1.65902 38.6284 0 -0 0</wrench>
            </link>
            <link name="front_right_wheel">
               <pose>-3.45145 -10.1498 0.184588 3.14159 0.280816 3.00118</pose>
               <velocity>-0.007005 0.000663 0.007239 -0.003733 -0.038923 -0.001471</velocity>
               <acceleration>-1.13991 0.659872 14.5683 0.023019 -0.065998 0.009324</acceleration>
               <wrench>-3.00446 1.73922 38.3977 0 -0 0</wrench>
            </link>
         </model>
         <model name="youbot">
            <pose>1.99999 -4.3e-05 0.090808 -8e-06 2.6e-05 0.001483</pose>
            <link name="arm_link_0">
               <pose>2.14299 0.00017 0.136802 -3e-06 2.8e-05 0.001483</pose>
               <velocity>7.2e-05 6.2e-05 -0.000125 -0.002585 -0.000337 0.001547</velocity>
               <acceleration>0.035974 -0.016673 -0.369995 0.009406 -0.034296 0.031934</acceleration>
               <wrench>0.030398 -0.014089 -0.312646 0 -0 0</wrench>
            </link>
            <link name="arm_link_1">
               <pose>2.16699 0.000206 0.232801 -4e-06 -3.1e-05 2.96852</pose>
               <velocity>1e-05 0.000188 -8.9e-05 -0.005441 -0.000114 0.003391</velocity>
               <acceleration>-0.238797 -0.267296 -0.328618 -0.000562 -0.005781 0.020127</acceleration>
               <wrench>-0.575978 -0.644719 -0.792628 0 -0 0</wrench>
            </link>
            <link name="arm_link_2">
               <pose>2.13449 0.005889 0.251801 -4e-05 -1.1345 2.96853</pose>
               <velocity>4e-05 0.000176 9.4e-05 -0.009186 -0.004903 0.011076</velocity>
               <acceleration>-0.788657 -0.678924 -0.412927 -0.003289 -0.035768 0.048049</acceleration>
               <wrench>-0.910899 -0.784157 -0.476931 0 -0 0</wrench>
            </link>
            <link name="arm_link_3">
               <pose>2.27287 -0.018304 0.317286 0.00053 1.41375 2.96902</pose>
               <velocity>-0.00023 0.001132 0.004032 -0.005545 -0.078286 0.009486</velocity>
               <acceleration>0.22999 0.11625 -0.098806 0.002332 -0.238113 0.006132</acceleration>
               <wrench>0.21481 0.108578 -0.092284 0 -0 0</wrench>
            </link>
            <link name="arm_link_4">
               <pose>2.14152 0.004663 0.338399 0.000116 -0.375287 2.96846</pose>
               <velocity>-0.002173 0.000137 -0.005163 0.014564 0.009449 0.01029</velocity>
               <acceleration>-2.28719 -0.473997 -9.59315 0.019384 -0.01327 0.013839</acceleration>
               <wrench>-2.00587 -0.415695 -8.41319 0 -0 0</wrench>
            </link>
            <link name="arm_link_5">
               <pose>2.1903 -0.003854 0.458619 -0.175792 0.333301 -0.670219</pose>
               <velocity>-0.000671 -0.001532 -0.005562 0.00097 0.01193 0.001112</velocity>
               <acceleration>-2.70945 -2.7089 -8.49411 0.022736 -0.000129 0.011074</acceleration>
               <wrench>-0.680071 -0.679935 -2.13202 0 -0 0</wrench>
            </link>
            <link name="base_footprint">
               <pose>1.99999 -4.3e-05 0.090808 -8e-06 2.6e-05 0.001483</pose>
               <velocity>7.8e-05 -5.6e-05 -0.000386 -0.001098 -0.000739 0.000237</velocity>
               <acceleration>0.302104 0.188145 -0.909846 1.06419 -0.385735 -0.404828</acceleration>
               <wrench>0.03021 0.018814 -0.090985 0 -0 0</wrench>
            </link>
            <link name="base_laser_front_link">
               <pose>2.29999 0.000402 0.0608 -8e-06 2.6e-05 0.001483</pose>
               <velocity>0.0001 -2e-05 -0.000173 -0.001091 -0.000739 0.000216</velocity>
               <acceleration>0.246852 0.048317 -0.080112 -2.09088 -1.40012 2.89663</acceleration>
               <wrench>0.039496 0.007731 -0.012818 0 -0 0</wrench>
            </link>
            <link name="base_link">
               <pose>1.99999 -4.3e-05 0.090808 -8e-06 2.6e-05 0.001483</pose>
               <velocity>7.9e-05 -5.6e-05 -0.000386 -0.001102 -0.000733 0.000239</velocity>
               <acceleration>0.163106 0.104582 -0.910515 0.410746 -0.718491 0.040652</acceleration>
               <wrench>3.58833 2.30081 -20.0313 0 -0 0</wrench>
            </link>
            <link name="caster_link_bl">
               <pose>1.77175 0.157619 0.056832 -8e-06 2.6e-05 0.000788</pose>
               <velocity>5.9e-05 -0.000156 0.000445 -0.001125 -0.000739 0.00012</velocity>
               <acceleration>0.311487 0.237867 0.180599 0.22365 -0.417126 -0.002096</acceleration>
               <wrench>0.031149 0.023787 0.01806 0 -0 0</wrench>
            </link>
            <link name="caster_link_br">
               <pose>1.77222 -0.158381 0.05683 -8e-06 2.6e-05 0.000777</pose>
               <velocity>0.000136 -0.000158 -0.00441 -0.001027 -0.000745 0.000117</velocity>
               <acceleration>0.202268 0.236349 -4.54603 0.233185 -0.418851 -0.00195</acceleration>
               <wrench>0.020227 0.023635 -0.454602 0 -0 0</wrench>
            </link>
            <link name="caster_link_fl">
               <pose>2.22775 0.158295 0.056829 -8e-06 2.6e-05 0.000578</pose>
               <velocity>5.7e-05 -4.5e-05 0.000602 -0.001143 -0.000724 0.00012</velocity>
               <acceleration>0.310535 0.080709 0.015958 0.225085 -0.416072 -0.002063</acceleration>
               <wrench>0.031053 0.008071 0.001596 0 -0 0</wrench>
            </link>
            <link name="caster_link_fr">
               <pose>2.22822 -0.157705 0.056833 -9e-06 2.6e-05 0.000557</pose>
               <velocity>0.000136 -4.5e-05 0.000539 -0.001138 -0.000719 0.000119</velocity>
               <acceleration>0.202299 0.080441 0.076264 0.223624 -0.415936 -0.002084</acceleration>
               <wrench>0.02023 0.008044 0.007626 0 -0 0</wrench>
            </link>
            <link name="gripper_finger_link_l">
               <pose>2.22092 0.006641 0.496885 0.175792 -0.333303 2.47138</pose>
               <velocity>0.002674 0.002429 -0.006783 0.001883 0.010081 -0.001492</velocity>
               <acceleration>-0.165818 0.060286 -9.19255 -1.94537 0.303503 2.04781</acceleration>
               <wrench>-0.001658 0.000603 -0.091926 0 -0 0</wrench>
            </link>
            <link name="gripper_finger_link_r">
               <pose>2.20534 -0.015556 0.50143 -0.175792 0.333303 -0.67022</pose>
               <velocity>0.002687 0.002443 -0.006681 0.002002 0.010052 -0.00154</velocity>
               <acceleration>-0.26733 0.078197 -9.45143 -1.8782 0.26959 2.0195</acceleration>
               <wrench>-0.002673 0.000782 -0.094514 0 -0 0</wrench>
            </link>
            <link name="gripper_palm_link">
               <pose>2.1903 -0.003854 0.458619 -0.175792 0.333303 -0.67022</pose>
               <velocity>-0.000744 -0.001754 -0.005585 0.001828 0.010095 -0.00147</velocity>
               <acceleration>-2.75389 -3.01103 -8.53744 1.05922 0.031756 -0.422363</acceleration>
               <wrench>-0.275389 -0.301103 -0.853744 0 -0 0</wrench>
            </link>
            <link name="plate_link">
               <pose>1.84099 -0.000278 0.136812 -8e-06 2.6e-05 0.001483</pose>
               <velocity>4.5e-05 -4.4e-05 -0.0005 -0.001113 -0.000716 0.000239</velocity>
               <acceleration>0.035294 0.083263 -1.35462 0.01667 -0.027765 -0.003508</acceleration>
               <wrench>0.035294 0.083263 -1.35462 0 -0 0</wrench>
            </link>
            <link name="wheel_link_bl">
               <pose>1.77175 0.157619 0.056831 -9e-06 2.1e-05 0.000788</pose>
               <velocity>6.2e-05 -0.000153 0.000384 -0.001136 0.000386 0.000121</velocity>
               <acceleration>0.31231 0.239335 0.107525 0.050023 5.3e-05 0.000512</acceleration>
               <wrench>0.124924 0.095734 0.04301 0 -0 0</wrench>
            </link>
            <link name="wheel_link_br">
               <pose>1.77222 -0.158381 0.056829 -8e-06 2.1e-05 0.000777</pose>
               <velocity>0.000138 -0.000155 -0.004128 -0.000969 0.000394 0.000113</velocity>
               <acceleration>0.202295 0.237862 -4.32871 0.05408 5.6e-05 0.000489</acceleration>
               <wrench>0.080918 0.095145 -1.73148 0 -0 0</wrench>
            </link>
            <link name="wheel_link_fl">
               <pose>2.22775 0.158295 0.056828 -9e-06 2.1e-05 0.000578</pose>
               <velocity>6e-05 -4.3e-05 0.000544 -0.00115 0.000386 0.000121</velocity>
               <acceleration>0.311404 0.081011 0.01591 0.051046 4.1e-05 0.0005</acceleration>
               <wrench>0.124562 0.032404 0.006364 0 -0 0</wrench>
            </link>
            <link name="wheel_link_fr">
               <pose>2.22822 -0.157705 0.056832 -9e-06 2.1e-05 0.000557</pose>
               <velocity>0.000137 -4.3e-05 0.000508 -0.00114 0.000387 0.00012</velocity>
               <acceleration>0.202328 0.08074 0.045487 0.050429 3.9e-05 0.000505</acceleration>
               <wrench>0.080931 0.032296 0.018195 0 -0 0</wrench>
            </link>
         </model>
      </state>
      <gui fullscreen="0">
         <camera name="user_camera">
            <pose>14.9781 -22.9767 20.3018 0 0.663643 2.26019</pose>
            <view_controller>orbit</view_controller>
         </camera>
      </gui>
   </world>
</sdf>
